Workbook

Sheet Hadapan
F1: JABATAN PEMBANGUNAN KEMAHIRAN KEMENTERIAN SUMBER MANUSIA | Y1: JPK/SLDN/LP01 COPTPA 2023
A5: LAPORAN LAWATAN PANEL PENENTUSAHAN PENTAULIAHAN PROGRAM KEMAHIRAN
A7: NAMA PLK/PB SLDN
A8: KOD PB SLDN (jika ada) | O8: TARIKH PENTAULIAHAN
A9: TARIKH LAWATAN | O9: KOD PB MOSQ (jika ada) | Y9: -
A11: JENIS SYARIKAT/ AGENSI | H11: Kerajaan / Badan Berkanun | S11: Syarikat Berkaitan Kerajaan (GLC)
H13: Perusahaan Kecil & Sederhana (PKS) | S13: Syarikat Multinasional (MNC)
A15: KATEGORI PENENTUSAHAN | J15: / | K15: Biasa
K17: Induk. Nyatakan Nama PLK/PB Induk:_______________________________________
A19: MAKLUMAT PERMOHONAN
A20: 1 : KATEGORI PENYEDIA LATIHAN KEMAHIRAN (PLK) / PB
B22: / | D22: PUSAT LATIHAN | X22: SYARIKAT
D24: SYARIKAT LATIHAN DALAMAN (IN-HOUSE)
A26: 2 : JENIS PERMOHONAN PENTAULIAHAN
G27: / | H27: PROGRAM PENUH | R27: PROGRAM MICRO CREDENTIAL (MC)
D30: PROGRAM BAHARU | Q30: PEMBAHARUAN PROGRAM
B32: / | D32: PENAMBAHAN PROGRAM | Q32: PINDAAN MAKLUMAT:
S33: Nama PB SLDN | Z33: Tambah Premis / Cawangan
S34: Alamat PB SLDN | Z34: Kapasiti Program
A36: Tandakan ( / ) pada ruangan berkaitan
A38: A. VERIFIKASI DOKUMEN UMUM / PREMIS
A39: BIL | B39: PERKARA | X39: ADA | Y39: TIADA | AA39: CATATAN
A40: 1 | B40: Semakan dokumen asal (original) berdasarkan senarai semak permohonan
B41: a. | C41: Salinan *SSM/JPPM/SKM/PBT Sabah&Sarawah/Agensi kerajaan
B42: b. | C42: Pendaftaran dengan Pihak Berkuasa Tempatan (PBT) yang masih sah (dikecualikan bagi agensi Kerajaan/Badan Berkanun)
B43: c. | C43: Pendaftaran dengan agensi pelesenan:Jab. Kebajikan Masyarakat/Kem. Pelancongan/Kem. Kesihatan/Jab. Perhilitan/Majlis Agama Islam/Kem. Pelajaran (jika berkenaan)
B44: d | C44: Dokumen pemilikan premis atau perjanjian sewaan - dikecualikan bagi agensi Kerajaan/Badan Berkanun.
A45: 2 | B45: Premis beroperasi di alamat seperti yang dinyatakan dalam borang permohonan
A46: 3 | B46: Keselamatan premis
B47: b | C47: Mempunyai alat pemadam kebakaran dan berada di tempat yang sesuai
B48: c | C48: Menyediakan pelan kebakaran bagi keseluruhan premis
B49: d | C49: Menyediakan laluan kecemasan, petujuk "KELUAR", "UTAMAKAN KESELAMATAN"

Sheet B Verifikasi Kurikulum Bdg 1 da
A1: B1. VERIFIKASI KURIKULUM MODUL TERAS (BIDANG 1 COPTPA)
A2: KOD PROGRAM / NAMA PROGRAM
A3: A : RANCANGAN PENGAJARAN & PEMBELAJARAN | C3: C01 | D3: C02 | E3: C03 | F3: C04 | G3: C05 | H3: C08 | I3: C09 | J3: C10 | K3: Catatan
A4: A1 | B4: Jadual Perancangan Pelaksanaan | C4: ADA / TIADA
A5: A2 | B5: Senarai Kandungan Kurikulum (KM01) lampiran 3 * Jadual gabungan PL dan Syarikat
A6: A3 | B6: Nota/Modul/Kertas Penerangan
A7: A4 | B7: Proses Kerja berdasarkan NOSS (JPK/SLDN/PK01)(Untuk Kategori Syarikat Latihan Dalaman (In-HOUSE) dan Syarikat SLDN sahaja)
A8: B : PENILAIAN BERTERUSAN (bagi permohonan pembaharuan program sahaja) | C8: C01 | D8: C02 | E8: C03 | F8: C04 | G8: C05 | H8: C08 | I8: C09 | J8: C10 | K8: Catatan
A9: Penilaian Pengetahuan
A10: B1 | B10: Ujian Teori i.Kertas Tugasan ii.Kuiz | C10: TIDAK BERKAITAN | K10: -
A11: B2 | B11: Lain-lain (laporan teknikal,laporan perbincangan/ lawatan tapak, kajian kes, persembahan dan lain-lain yang sesuai) | C11: TIDAK BERKAITAN | K11: -
A12: Penilaian Prestasi (terpakai untuk kategori Syarikat in-house sahaja)
A13: B3 | B13: Ujian Amali i.Proses kerja ii.Hasil kerja (produk/servis/keputusan) iii.Sikap/keselamatan iv.Lisan Ujian amali boleh dilaksanakan dalam bentuk mini projek TVET, Case study, simulasi, bukti-bukti rekod kerja di bengkel. Pembaharuan Program Sahaja *Latihan melalui kertas kerja tidak diambil kira sebagai ujian amali | C13: TIDAK BERKAITAN | K13: -
A14: C: PENILAIAN AKHIR | C14: C01 | D14: C02 | E14: C03 | F14: C04 | G14: C05 | H14: C08 | I14: C09 | J14: C10 | K14: Catatan
A15: Penilaian Akhir Kendiri (Dalaman)
A16: C1 | B16: i.Penilaian Akhir Pengetahuan ii.Penilaian Akhir Prestasi (Merujuk kepada panduan pembangunan soalan penilaian latihan kemahiran yang sedang berkuatkuasa) | C16: TIDAK BERKAITAN | K16: -
A17: Penilaian Akhir Verifikasi PPL
A18: C2 | B18: i.Penilaian Akhir Pengetahuan ii.Penilaian Akhir Prestasi (Merujuk kepada panduan pembangunan soalan penilaian latihan kemahiran yang sedang berkuatkuasa) | C18: TIDAK BERKAITAN | K18: -
A19: B2. VERIFIKASI KURIKULUM MODUL WAJIB (BIDANG 1 COPTPA)
A20: A : CORE ABILITY (CA) (semasa permohonan pembaharuan sahaja) | C20: Kertas Penerangan/ Nota Latihan | G20: Kertas Penilaian Pengetahuan | I20: Kertas Penilaian Prestasi | M20: Catatan
A21: 1 | B21: CA (TAHAP 1) | C21: ADA / TIADA / TIDAK BERKAITAN | G21: ADA / TIADA / TIDAK BERKAITAN | K21: TIADA | M21: TIDAK DISERTAKAN
A22: 2 | B22: CA (TAHAP 2) | C22: ADA / TIADA / TIDAK BERKAITAN | G22: ADA / TIADA / TIDAK BERKAITAN | K22: TIADA | M22: TIDAK DISERTAKAN
A23: 3 | B23: CA (TAHAP 3) | C23: ADA / TIADA / TIDAK BERKAITAN | G23: ADA / TIADA / TIDAK BERKAITAN | K23: TIADA | M23: TIDAK DISERTAKAN
A24: 4 | B24: CA (TAHAP 4) | C24: ADA / TIADA / TIDAK BERKAITAN | G24: ADA / TIADA / TIDAK BERKAITAN | K24: TIDAK BERKAITAN | M24: TIDAK BERKAITAN
A25: 5 | B25: CA (TAHAP 5) | C25: ADA / TIADA / TIDAK BERKAITAN | G25: ADA / TIADA / TIDAK BERKAITAN | K25: TIDAK BERKAITAN | M25: TIDAK BERKAITAN
A26: B : MODUL PENYEDIA TVET (ISI YANG BERKAITAN | C26: Rangka Kursus (Course Outline) | G26: PKK Teori / PKK Amali / Penilaian Akhir Teori / Penilaian Akhir Amali | I26: Catatan

Sheet C Verifikasi Personel+JPS Bdg 4
A1: C1 : SEMAKAN PERSONEL (BIDANG 4 COPTPA)
A2: BIL | B2: LANTIKAN (PPB/Pengajar/Coach/ Penyelaras) | C2: NAMA | D2: SURAT LANTIKAN DAN TERIMA MENGIKUT PROGRAM (ADA/TIADA) | E2: SIJIL INDUKSI SLDN (ADA/TIADA) | F2: PENGIKTIRAFAN PERSONEL (ADA/TIADA) | G2: SKM / DKM / DLKM (TANDA YANG BERKAITAN) | H2: DIPLOMA / IJAZAH a)Diploma / Ijazah dalam bidang dan 2 tahun pengalaman kerja; atau b)Diploma / Ijazah sarjana muda TVET dalam program yang berkaitan (ADA / TIADA) | I2: SIJIL TEKNIK MENGAJAR VTO / VTE / VTM / Pengajaran TVET (TVET-i) / Pengurusan TVET (TVET-m) | J2: Sijil Teknik Mengajar yang diluluskan oleh KPPK (ADA / TIADA) | K2: Sijil Bagi Program yang Melibatkan Agensi Penguatkuasaan atau Badan Pelesenan (ADA / TIADA) | L2: PENGALAMAN (TAHUN) | N2: Catatan
L3: KERJA DALAM BIDANG | M3: MENGAJAR DALAM BIDANG
A4: 1
A5: 2
A6: 3
A7: 4
A8: 5
A9: 6
A10: SYOR
A11: NOTA i.Personel yang dilantik sebagai Pengajar dan Coach hendaklah individu yang berlainan. ii.Personel Pengajar (Sepenuh Masa) yang berstatus pekerja tetap. iii.Pengajar separuh masa boleh dilantik tetapi tidak boleh melebihi 40% dari jumlah keseluruhan pengajar. *rujuk panduan yang sedang berkuatkuasa dokumen asal hendaklah dikemukakan kepada panel semasa lawatan
A12: C2 : SEMAKAN JAWATANKUASA PENILAIAN (hanya untuk permohonan pembaharuan program sahaja)
A13: (ADA/ TIADA/TIDAK BERKAITAN)
A14: Nota: Setiap bidang hendaklah mempunyai Jawatankuasa Penilaian yang berlainan.

Sheet D Verifikasi FIZIKAL Bdg 5
A1: D. VERIFIKASI FIZIKAL (BIDANG 5 COPTPA)
A2: D1 : SENARAI PERALATAN DAN KEMUDAHAN TEORI BERDASARKAN CU/Duti/WA/Task (JPK/PP01)
A3: Bil | B3: PERKARA | D3: STATUS | F3: CATATAN
A4: 1 | B4: Semakan Peralatan ( Meja / Kerusi / AVA dan lain- lain) | D4: Peraku / Tidak Diperaku
A5: 2 | B5: Peralatan Simulasi/ Pelesenan program | D5: Ada / Tiada / Tidak Berkaitan
A6: 3 | B6: Verifikasi Bilik Teori | D6: KAPASITI | E6: PENCAHAYAAN | F6: CATATAN
B7: i. Kapasiti perantis bagi setiap kelas/bilik latihan. | C7: Kelas/Bilik Kuliah 1 | E7: Sesuai / Tidak Sesuai
C8: Kelas/Bilik Kuliah 2 | E8: Sesuai / Tidak Sesuai
C9: Kelas/Bilik Kuliah 3 | E9: Sesuai / Tidak Sesuai
B10: ii. Kapasiti perantis keseluruhan jika program berjalan serentak
A11: D2 : SENARAI PERALATAN DAN KELENGKAPAN PRAKTIKAL BERDASARKAN CU/Duti/WA/Task (JPK/PS01) ( Untuk SYARIKAT LATIHAN DALAMAN (IN-HOUSE) sahaja)
A12: Bil | B12: Perkara | D12: STATUS / KAPASITI | F12: CATATAN
A13: 1 | B13: Semakan Peralatan Berdasarkan CU/Duti/WA/Task | D13: Peraku / Tidak Diperaku
A14: 2 | B14: Premis sesuai untuk latihan praktikal | D14: Peraku / Tidak Diperaku
A15: 3 | B15: Pencahayaan dan pengudaraan dalaman sesuai untuk latihan praktikal | D15: Sesuai / Tidak Sesuai
A16: 4 | B16: Kapasiti perantis keseluruhan jika program berjalan serentak | D16: -
A17: D3: VERIFIKASI PERALATAN DI SYARIKAT / AGENSI / PREMIS LUAR (jika berkaitan)
A18: CU/Duti/WA/Task terlibat :
A19: Bil | B19: Perkara | D19: STATUS | F19: CATATAN
A20: 1 | B20: Penilaian Proses Kerja (JPK/PK01) | F20: -
A21: 2 | B21: Penilaian Peralatan berdasarkan CU/Duti/WA/Task (JPK/PS01)
A22: 3 | B22: Premis sesuai untuk latihan praktikal
A23: 4 | B23: MOU
A24: 5 | B24: Nama dan Alamat Agensi / Premis Luar

Sheet E COPTPA
A1: E: PENILAIAN KRITERIA DAN STANDARD PENTAULIAHAN PROGRAM (COPTPA)
A2: Jenis permohonan: B – Program Baharu P – Pembaharuan T – Penambahan program | F2: Kategori Skala Penilaian: | G2: Skor mengikut kategori penilaian
F3: P=Pengurusan/ Proses | G3: Dokumen/lisan/pemerhatian: 0 –Tiada (0%) 1 –Ada dan dilaksanakan sebahagiannya (<50%) 2 –Ada dan dilaksanakan sebahagiannya (50% sehingga 90%) 3 –Dilaksanakan sepenuhnya (>90%)
F4: D=Dokumen | G4: Softcopy/hardcopy: 0 –Tiada (0%) 1 –Ada dan tidak lengkap (<50%) 2 –Ada dan lengkap sebahagian (50% sehingga 90%) 3 –Lengkap (>90%)
F5: F=Fizikal | G5: 0 –Tiada (0%) 1 –Ada sebahagian yang selamat atau berfungsi (<50 %) 2 –Ada sebahagian yang selamat atau berfungsi (50% sehingga 90%) 3 –Memenuhi dari segi bilangan, keselamatan dan kefungsian (>90%)
A6: BIDANG 1: PEMBANGUNAN DAN PENYAMPAIAN PROGRAM
A7: STANDARD TVET | C7: JENIS PERMOHONAN | F7: PANDUAN KEPADA APV | G7: RUBRIK PEMARKAHAN | H7: KATEGORI SKALA PENILAIAN | I7: PEMBERAT | J7: SKOR | K7: JUMLAH SKOR | L7: CATATAN
A8: 1.1 | B8: Objektif Pendidikan Program | C8: B | D8: P | E8: T | H8: =IF(Hadapan!B30<>"","B",IF(Hadapan!P30<>"","P",IF(Hadapan!B32<>"","T",""))) -> T | K8: {=IF(F8:F28="","",IF((I8:I28*J8:J28)=0,"",(I8:I28*J8:J28)))}
A9: 1.1.1 | B9: Objektif program mestilah selari dengan visi, misi dan matlamat PLKT/Penyedia TVET. | C9: √ | E9: √ | F9: Menyemak a. Kesesuaian objektif program yang disediakan b. Hubung kait antara visi, misi dan matlamat PLK/PB dengan objektif program. Contoh bukti yang dilihat seperti: i. Website ii. Student’s handbook; iii. Poster iv. Brosur; v. Profil Syarikat (Company profile); atau vi. Apa-apa dokumen yang menerangkan visi, misi dan matlamat dengan objektif program | G9: 0 - Tiada 1 - Ada misi, visi dan matlamat tetapi tiada objektif program. 2 - Ada objektif program tetapi tidak sesuai dengan visi, misi dan matlamat Penyedia TVET. 3 - Objektif program selari dengan visi, misi dan matlamat Penyedia TVET. | H9: D | I9: 1
A10: 1.2 | B10: Hasil Pembelajaran Program | C10: B | D10: P | E10: T
A11: 1.2.1 | B11: Program mestilah selari dan menyokong visi, misi dan sasaran PLKT/Penyedia TVET | C11: √ | E11: √ | F11: Menyemak sama ada visi, misi dan matlamat adalah selari dengan PLO (Program Learning Outcome) bagi melahirkan graduan dalam jurusan/bidang yang disasarkan oleh PLK/PB. | G11: 0 - Tiada 1 - Ada misi, visi dan matlamat tetapi tiada hasil pembelajaran. 2 - Ada misi, visi dan matlamat dan ada hasil pembelajaran tetapi tidak sesuai. 3 - Misi, visi dan matlamat selari dengan hasil pembelajaran. | H11: P | I11: 1
A12: 1.2.2 | B12: Penawaran program mestilah berlandaskan dapatan penilaian tentang keperluan program. PLKT/Penyedia TVET mestilah mempunyai jawatan kuasa rasmi yang bertanggungjawab mengendalikan sesi konsultasi dengan pihak dalaman dan luaran, kajian pasaran, analisis keperluan pekerjaan dan menjangka kebolehpasaran graduan program selari dengan perkembangan teknologi dan bidang program. | C12: √ | E12: √ | F12: Menilai dan mengesahkan program yang dilaksanakan dengan mengambil kira kajian pasaran, analisis keperluan pekerjaan dan menjangka kebolehpasaran. Semakan boleh mengambil kira perkara berikut: i. Jawatankuasa kajian pasaran program Carta organisasi PPPB /Jawankuasa Penilaian; ii. Laporan kajian / Minit Mesyuarat PPPB/Jawankuasa Penilaian ; atau iii. Dokumen lain yang berkaitan | G12: 0 - Tiada 1 – Memenuhi salah 1 penilaian keperluan program. 2 - Memenuhi sekurang-kurangnya 2 penilaian keperluan program. 3 - Memenuhi semua penilaian keperluan program. | H12: P | I12: 1
A13: 1.2.3 | B13: Objektif, hasil pembelajaran, penyampaian program TVET mesti dinyatakan dengan jelas dan perlu mencakupi strategi pengajaran dan pembelajaran,penilaian dan penjajaran konstuktif diantaranya. | C13: √ | E13: √ | F13: Menilai perkaitan antara hubung kait antara objektif, hasil pembelajaran dan strategi pelaksanaan program berdasarkan maklumat yang dibekalkan. | G13: 0 - Tiada 3 - Ada | H13: P | I13: 1
A14: 1.2.4 | B14: PLO mesti sesuai dengan diskripsi tahap dan lima kluster hasil pembelajaran yang dinyatakan dalam MQF. Lima kluster hasil pembelajaran seperti berikut: i. Pengetahuan dan pemahaman ii. Kemahiran kognitif iii. Kemahiran kefungsian kerja (kemahiran praktikal/ interpersonal/ komunikasi/ digital/ kepimpinan iv. Kemahiran keusahawanan* v. Etika dan profesionalisma | C14: √ | E14: √ | F14: Menilai dan mengesahkan kefahaman PLK/PB berkaitan hasil pembelajaran dalam program merujuk kepada 5 kluster hasil pembelajaran. | G14: 0 - Tiada 3 - Ada | H14: P | I14: 1
A15: 1.2.5 | B15: Berdasarkan Hasil Pembelajaran yang dinyatakan, senaraikan kerjaya dan pilihan menyambung pengajian apabila pelajar telah menamatkan pengajian mereka. | C15: √ | E15: √ | F15: Menilai dan mengesahkan laluan peluang kerjaya dan pengajian yang boleh diterima pelajar. Contoh bukti yang dilihat seperti: i. Website; ii. Student’s handbook; iii. Poster; iv. Brosur; atau v. Dokumen lain yang berkaitan | G15: 0 - Tiada 1 – Ada salah satu elemen; Laluan peluang kerjaya atau pengajian. 3 - Ada kedua-dua elemen; Laluan peluang kerjaya dan pengajian. | H15: D | I15: 1
A16: 1.3 | B16: Pembangunan Program | C16: B | D16: P | E16: T
A17: 1.3.1 | B17: TVET program hanya boleh dipertimbangkan jika kurikulum program tersebut dibangunkan berlandaskan Occupational / Industry Standards and Practices (OISP) atau NOSS. | C17: √ | E17: √ | F17: Mengesahkan program menepati keperluan yang ditetapkan NOSS. | G17: 0 - Tiada 3 - Ada | H17: D | I17: 3
A18: 1.3.2 | B18: Kurikulum yang ditawarkan mestilah memenuhi keperluan OISP yang dinyatakan, standard TVET, standard program (yang berkaitan), keperluan profesional,keperluan industri, amalan baik yang selari dengan teknologi baharu dan akan datang. (Standard ini turut merujuk 1.3.3) | C18: √ | D18: √ | E18: √ | F18: Menyemak, menilai dan mengesahkan maklumat program dan kurikulum menepati keperluan yang ditetapkan NOSS dan peraturan serta panduan pelaksanaan yang sedang berkuat kuasa. | G18: 0 - Tiada 3 - Ada | H18: D | I18: 3
A19: 1.3.4 | B19: Penyedia TVET mestilah mempunyai autonomi dalam mereka bentuk kurikulum dan menggunapakai sumber berkaitan seperti ketetapan OISP. | C19: √ | D19: √ | E19: √ | F19: Mengesahkan kandungan dan struktur latihan. Antara bukti yang disemak seperti: i. Kurikulum, ii. Senarai modul dan jam kredit; atau iii. Jadual pelaksanaan latihan. | G19: 0 - Tiada 1 – Tidak lengkap <50% 2 - Tidak lengkap >50% 3 - Lengkap | H19: P | I19: 3
A20: 1.3.7 | B20: Penyedia TVET mestilah menjalankan aktiviti yang boleh memperkayakan pengalaman dan meningkatkan perkembangan diri pelajar. (tidak terpakai kepada program ODL dan program yang dibangunkan untuk pelajar matang) | C20: √ | D20: √ | E20: √ | F20: Komen kesesuaian aktiviti yang disediakan oleh Penyedia TVET dalam meningkatkan pengalaman dan perkembangan diri pelajar. *Nota: Pendedahan industri bagi program SLDN / ADI diberikan secara automatik | G20: 0 - Tiada 1 – Ada 1 atau 2 bukti 2 - Ada 3 bukti 3 - Ada semua bukti | H20: P | I20: 3
A21: 1.4 | B21: Penyampaian Program | C21: B | D21: P | E21: T
A22: 1.4.1 | B22: Penyedia TVET mestilah bertanggungjawab dalam memastikan keberkesanan penyampaian hasil pembelajaran program. | D22: √ | F22: Menyemak borang maklum balas dan laporan analisa bagi keberkesanan hasil pembelajaran program. Contoh bukti yang dilihat seperti: i. Borang maklum balas program; ii. Analisa maklum balas program iii. Minit Mesyuarat; atau iv. Dokumen-dokumen lain yang boleh menyokong maklumat tersebut. | G22: 0 - Tiada 1 – Ada borang maklumbalas sahaja 2 – Ada borang dan analisa sahaja 3 – Ada borang, analisa dan dibentangkan | H22: D | I22: 3
A23: 1.4.2 | B23: Maklumat berkaitan objektif, struktur, outline kursus, jadual, jam kredit, LO, kaedah penilaian program dan lain-lain maklumat terkini berkaitan program wajib disampaikan kepada pelajar. | D23: √ | F23: Menyemak dan mengesahkan maklumat terkini disampaikan kepada pelatih/perantis. Contoh bukti yang dilihat seperti: i. Website; ii. Panduan Pelajar (Student’s handbook); iii. Poster; iv. Brosur; atau v. Dokumen-dokumen lain yang boleh menyokong maklumat tersebut. | G23: 0 - Tiada 1 – Ada sebahagian daripada maklumat. 2 – Ada objektif, struktur, outline kursus, jadual, jam kredit, LO, kaedah penilaian program 3 - Ada objektif, struktur, outline kursus, jadual, jam kredit, LO, kaedah penilaian program dan disampaikan kepada pelajar | H23: D | I23: 1
A24: 1.4.3 | B24: Koordinator sepenuh masa dan tenaga pengajar TVET (contoh jawatankuasa program) mesti dilantik dan diberi kuasa untuk memastikan pengendalian program dapat dilakukan secara berkesan. | C24: √ | E24: √ | F24: Membuat semakan dan pengesahan pelantikan koordinator, tenaga pengajar dan Panel Penilaian Pusat Bertauliah (PPPB) / Jawatankuasa Penilaian SLDN. Antara bukti yang dilihat seperti: i. Surat pelantikan ii. Carta organisasi iii. Minit mesyuarat PPPB/Jawatankuasa Penilaian | G24: 0 - Tiada 1 – Surat lantikan sahaja 2 – Surat PPKSPP bagi Pengajar 3 – Semua dokumen surat lantikan, PPKSPP dan JD. | H24: P | I24: 3
A25: 1.4.4 | B25: Penyedia TVET diwajibkan untuk menyediakan persekitaran yang kondusif untuk proses pengajaran dan pembelajaran | C25: √ | E25: √ | F25: Menyemak dan mengesahkan: i. Bilik kuliah dan bengkel disediakan ii. Sistem pencahayaan dan pengudaraan yang baik iii. Persekitaran yang sesuai dan kondusif iv. Keselamatan premis latihan dan bengkel di patuhi (disertakan pengesahan dari agensi berkaitan) | G25: 0 - Tiada / Ada tetapi tidak selamat. 1 - Ada tetapi tidak kondusif. 3 - Ada, selamat dan kondusif. Nota Standard ini dibaca bersama Standard 5.1 dalam bidang 5.0 Sumber Pendidikan. | H25: F | I25: 3
A26: 1.4.5 | B26: Penyedia TVET mestilah menggalakkan inovasi untuk proses pengajaran dan pembelajaran seperti Work Base Learning (WBL), pembelajaran mod campuran, pembelajaran atas talian, apprenticeship, projek dan sebagainya. | C26: √ | E26: √ | F26: Menyemak dan mengesahkan Pengesahan pelaksanaan kaedah pembelajaran yang bersesuaian dengan program. Antara bukti yang dilihat seperti: i. Pengajaran secara simulasi ii. E-learning iii.SLDN / Work-based learning atau apa-apa kaedah lain yang bersesuaian bagi pembelajaran dan pengajaran | G26: 0 - Tiada 1 – Ada salah satu 3 – Ada semua | H26: P | I26: 1
A27: 1.4.6 | B27: Penyedia TVET mestilah mendapatkan maklum balas/input daripada pihak berkepentingan untuk menambah baik penyampaian hasil pembelajaran program. | D27: √ | F27: Membuat semakan dan pengesahan terdapat kaedah mendapatkan maklum balas/input pihak berkepentingan. Contoh bukti yang dilihat seperti: i. Borang maklum balas majikan / course critique; ii. Minit mesyuarat atau laporan TAC / Jawatankuasa Penilaian / PPL; iii. Laporan pendedahan industri/ Latihan industri;atau iv. Bukti-bukti lain yang bersesuian. | G27: 0 - Tiada 1 – Ada maklumbalas sahaja 2 – Ada maklumbalas dan analisa sahaja 3 – Ada maklumbalas, analisa dan tindakan penambahbaikan | H27: D | I27: 3
A28: 1.4.7 | B28: Penyedia TVET mestilah sentiasa berhubungan dengan pihak industri bagi meningkatkan penyampaian program. | D28: √ | F28: Membuat semakan dan pengesahan bagaimana kerjasama industri dilaksanakan. Antara perkara yang boleh disemak: i. Minit mesyuarat Jawankuasa Penilaian; ii. Maklumbalas daripada pihak industri contohnya: buku log pelatih / perantis atau laporan; iii. Surat kerjasama / MoU; atau iv. Dokumen lain yang berkaitan | G28: 0 - Tiada 1 – TAC sahaja 2 – TAC dan MOU/NOU/LOI tetapi tiada aktiviti 3 – TAC dan MOU/NOU/LOI dan ada aktiviti | H28: P | I28: 3
A29: BIDANG 2: PENILAIAN PEMBELAJARAN PELAJAR
A30: STANDARD TVET | C30: JENIS PERMOHONAN | F30: PANDUAN KEPADA APV | G30: RUBRIK PEMARKAHAN | H30: KATEGORI SKALA PENILAIAN | I30: PEMBERAT | J30: SKOR | K30: JUMLAH SKOR | L30: CATATAN APV
A31: 2.1 | B31: Hubungan Antara Penilaian dan Hasil Pembelajaran | C31: B | D31: P | E31: T | K31: {=IF(F31:F47="","",IF((I31:I47*J31:J47)=0,"",(I31:I47*J31:J47)))}
A32: 2.1.1 | B32: Prinsip, kaedah dan amalan penilaian mestilah selari dengan pencapaian hasil pembelajaran program dan konsisten dengan tahap yang dinyatakan dalam MQF. | D32: √ | F32: Menyemak dan mengesahkan kaedah pelaksanaan penilaian. Antara bukti yang dilihat adalah dokumen penilaian kemahiran berkaitan | G32: 0 – Tiada 1 – Ada dan lengkap bagi 1 perkara daripada JPPKK/C/(A3&A4)/B3 2 - Ada dan lengkap 3 perkara daripada JPPKK/ C/ (A3&A4)/B3 3 – Semua dokumen telah dipenuhi * Dokumen Penilaian / Jadual pembangunan BPDP & Penilaian JPPKK/ C/ (A3&A4)/B3 ( Jadual Pembahagian Penilaian Kerja Kursus), C= PENILAIAN KERJA KURSUS (PKK) & PENILAIAN AKHIR DALAMAN (PAD) / PENILAIAN AKHIR (PA) BAGI MODUL TERAS A3 = Jadual Penetapan Peratusan Masa Aktiviti Pembelajaran Penilaian (JPPMAPP) A4 = Jadual Pembahagian Masa Pembelajaran Bersemuka (JPMPB) B3 = Kertas Tugasan (Assignment Sheet) | H32: D | I32: 3
A33: 2.1.2 | B33: Penjajaran antara penilaian dan pencapaian hasil pembelajaran program perlu disemak secara sistematik dan berkala untuk memastikan keberkesanan pengukurannya. | D33: √ | F33: Rujuk 2.1.1 | G33: 0 – Tiada 1 – Ada dan lengkap bagi 1 perkara daripada JPPKK/C/(A3&A4)/B3 2 - Ada dan lengkap 3 perkara daripada JPPKK/ C/ (A3&A4)/B3 3 – Semua dokumen telah dipenuhi | H33: D | I33: 3
A34: 2.1.3 | B34: Kaedah penilaian untuk mengukur kemahiran praktikal (domain psikomotor) perlu diselaraskan dengan tahap kompetensi untuk memastikan pencapaian kemahiran yang dinyatakan. | D34: √ | F34: Rujuk 2.1.1 | G34: 0 – Tiada 1 – Ada dan lengkap bagi 1 perkara daripada JPPKK/C/(A3&A4)/B3 2 - Ada dan lengkap 3 perkara daripada JPPKK/ C/ (A3&A4)/B3 3 – Semua dokumen telah dipenuhi | H34: D | I34: 3
A35: 2.1.4 | B35: Kaedah penilaian yang digunakan untuk mengukur kemahiran fungsional, personal dan etika mestilah selari dengan tahap kompetensi bagi memastikan hasil pembelajaran tercapai. | D35: √ | F35: Rujuk 2.1.1 | G35: 0 – Tiada 1 – Ada dan lengkap bagi 1 perkara daripada JPPKK/C/(A3&A4)/B3 2 - Ada dan lengkap 3 perkara daripada JPPKK/ C/ (A3&A4)/B3 3 – Semua dokumen telah dipenuhi | H35: D | I35: 3
A36: 2.2 Kaedah Penilaian
A37: 2.2.1 | B37: Kekerapan, kaedah dan kriteria penilaian pelajar (termasuk sistem penggredan dan dasar rayuan) perlu didokumenkan dan disebar luas kepada pelajar semasa program berjalan. | D37: √ | F37: Menyemak struktur dan jadual perancangan penilaian dan kaedah penyampaian maklumat kepada pelatih/perantis. Antara bukti yang dilihat seperti: i. Jadual pelaksanaan latihan dan penilaian ii. Rekod Bukti Penilaian iii. Notis Makluman / Website iv. Student’s handbook - Panduan berkaitan pelaksanaan dan penilaian latihan serta prosedur rayuan | G37: 0 – Tiada 1 – Ada dan lengkap bagi 1 daripada semua perkara 2 - Ada dan lengkap 2 perkara daripada semua perkara 3 – Semua dokumen dan prosedur dipenuhi | H37: D | I37: 3
A38: 2.2.2 | B38: Kaedah dan mekanisme penilaian mestilah pelbagai dan sesuai bagi menilai hasil pembelajaran dan kompetensi. | D38: √ | F38: Menyemak dan mengesahkan dokumen penilaian yang disediakan. Antara bukti yang dilihat seperti: i. Dokumen penilaian berterusan dan PenilaianAkhir (PA) ii. Penilaian secara dalam talian (Online assessment) iii. Projek Akhir | G38: 0 – Tiada 1 – Ada dan lengkap bagi 1 perkara daripada JPPKK/C/(A3&A4)/B3 2 - Ada dan lengkap 3 perkara daripada JPPKK/ C/ (A3&A4)/B3 3 – Semua dokumen telah dipenuhi | H38: P | I38: 1
A39: 2.2.3 | B39: Penyedia TVET hendaklah mempunyai mekanisme dan proses semakan kaedah penilaian pelajar secara berkala dalam memastikan kaedah penilaian yang digunapakai adalah sahih, boleh dipercayai dan terkini. | D39: √ | F39: Menyemak kesesuaian mekanisma dan proses semakan semula kaedah penilaian pelatih / perantis melalui penelitian terhadap perkara berikut: i. Carta alir Proses pembangunan soalan penilaian berterusan dan penilaian akhir. ii. Proses dan peranan PPPB / TAC / Jawankuasa Penilaian iii. Minit Mesyuarat PPPB/TAC/ Jawankuasa Penilaian iv. Dokumen lain yang berkaitan | G39: 0 – Tiada 1 – Ada lantikan PPPB/TAC & peranan 2 - Ada lantikan PPPB dan TAC & peranan 3 – Ada lantikan PPPB, lantikan TAC dan minit mesyuarat yang lengkap dan menyatakan perkara ini | H39: P | I39: 1
A40: 2.2.4 | B40: Perubahan terhadap kaedah penilaian pelajar hendaklah dilakukan selari dengan prosedur dan peraturan yang telah ditetapkan serta dimaklumkan kepada pelajar sebelum pelaksanaannya. | D40: √ | F40: Semakan dan mengesahkan mekanisma pemakluman kepada pelatih/perantis. Contoh bukti yang dilihat seperti: i. Notis hebahan/ Notis makluman ii. Website iii. Perhimpunan bulanan; iv. Dan lain-lain | G40: 0 – Ada perubahan tetapi tiada pemakluman 1 – Tiada perubahan kaedah penilaian / ada perubahan dan ada pemakluman | H40: P | I40: 1
...

Sheet F Syor
A1: F. ULASAN KESELURUHAN (Penemuan/ Komen/ Cadangan Penambahbaikan)
A20: G. COPTPA : PERATUSAN MARKAH DIPEROLEHI MENGIKUT BIDANG
A21: BIDANG | B21: BIDANG 1 (Pembangunan Dan Penyampaian Program) | C21: BIDANG 2 (Penilaian Pembelajaran Pelatih) | D21: BIDANG 3 (Pemilihan Pelatih dan Khidmat Sokongan) | F21: BIDANG 4 (Tenaga Pengajar) | G21: BIDANG 5 (Kemudahan) | H21: BIDANG 6 (Pengurusan Program) | I21: BIDANG 7 (Pemantauan Serta Semakan Semula Program Dan Penambahbaikan Kualiti Berterusan) | J21: PERATUSAN MARKAH KESELURUHAN
A22: % Markah | B22: =SUMIF('E COPTPA'!A9:A130,"1.*",'E COPTPA'!K9:K130) -> 0 | C22: =SUMIF('E COPTPA'!A9:A130,"2.*",'E COPTPA'!K9:K130) -> 0 | D22: =SUMIF('E COPTPA'!A9:A130,"3.*",'E COPTPA'!K9:K130) -> 0 | F22: =SUMIF('E COPTPA'!A9:A130,"4.*",'E COPTPA'!K9:K130) -> 0 | G22: =SUMIF('E COPTPA'!A9:A130,"5.*",'E COPTPA'!K9:K130) -> 0 | H22: =SUMIF('E COPTPA'!A9:A130,"6.*",'E COPTPA'!K9:K130) -> 0 | I22: =SUMIF('E COPTPA'!A9:A130,"7.*",'E COPTPA'!K9:K130) -> 0 | J22: ='E COPTPA'!K133 -> 0
A23: H. SYOR VERIFIKASI
A24: Bil | B24: Kod NOSS | F24: Syor Panel | I24: Kapasiti Program
A25: 1 | F25: Sokong / Tidak Sokong
A26: 2 | F26: Sokong / Tidak Sokong
A27: 3 | F27: Sokong / Tidak Sokong
A28: I. PERAKUAN PANEL
A29: Kami mengesahkan bahawa Lawatan Penentusahan Pentauliahan Program telah dilakukan terhadap permohonan ini. Kami juga bertanggungjawab sepenuhnya terhadap laporan penentusahan ini dan ianya mematuhi panduan pentauliahan yang sedang berkuatkuasa.
A48: J. PENGESAHAN PPB / PENGURUS PLK / WAKIL PLK/PB
A49: Dengan ini saya mengesahkan bahawa Panel telah melaksanakan penilaian dan memaklumkan hasil lawatan di PLK/PB seperti dinyatakan di atas.

Sheet Komen
A1: F. ULASAN KESELURUHAN (Penemuan/ Komen/ Cadangan Penambahbaikan)
A2: NOTA : 1. TAHAP 3 ada 6 kredit untuk LI. Kredit Latihan Industri (LI) diberikan secara automatik bagi pelaksaan SLDN. Kalu ikut minimum kedit bergraduat , kredit minimum tahap 3= 30 kredit. Bila tolak LI tinggal 24 kredit. 24 kredit x 40 = 960 jam. Adakah tempoh latihan boleh jadi 960 jam atau perlu buat 30x40= 1200 jam?

Sheet Verifikasi Sykt & SI
A1: G. VERIFIKASI PROGRAM DAN COACH DI SYARIKAT/SYARIKAT LATIHAN DALAMAN (IN-HOUSE)
A2: BIL | B2: KOD NOSS/ TAHAP | F2: KEMUDAHAN PRAKTIKAL | X2: MAKLUMAT COACH | AR2: CATATAN
F3: Proses Kerja (JPK/SLDN/PK01) | J3: Peralatan Berdasarkan CU/Duti/WA/Task (JPK/SLDN/PS01) | N3: Bahan Penilaian Praktikal | R3: NOSS Terkini | U3: MOU Dengan PB/PLK Lain (Kecuali SI) | X3: Nama Coach No KP Emel | AF3: Kursus SLDN | AJ3: Kehadiran Coach | AN3: Pengalaman Bekerja Berkaitan Program
A4: 1 | G4: Lengkap | K4: Lengkap | O4: Lengkap | S4: Ada | V4: Ada | AG4: Induksi | AK4: Hadir | AO4: < 3 Thn
G5: Separa | K5: Separa | O5: Separa | S5: Tiada | V5: Tiada | AG5: Coach | AK5: Tidak | AO5: ≥ 3 Thn
G6: Tiada | K6: Tiada | O6: Tiada | AG6: PPKSPP | AK6: THDI
A7: 2 | G7: Lengkap | K7: Lengkap | O7: Lengkap | S7: Ada | V7: Ada | AG7: Induksi | AK7: Hadir | AO7: < 3 Thn
G8: Separa | K8: Separa | O8: Separa | S8: Tiada | V8: Tiada | AG8: Coach | AK8: Tidak | AO8: ≥ 3 Thn
G9: Tiada | K9: Tiada | O9: Tiada | AG9: PPKSPP | AK9: THDI
A10: 3 | G10: Lengkap | K10: Lengkap | O10: Lengkap | S10: Ada | V10: Ada | AG10: Induksi | AK10: Hadir | AO10: < 3 Thn
G11: Separa | K11: Separa | O11: Separa | S11: Tiada | V11: Tiada | AG11: Coach | AK11: Tidak | AO11: ≥ 3 Thn
G12: Tiada | K12: Tiada | O12: Tiada | AG12: PPKSPP | AK12: THDI
A13: 4 | G13: Lengkap | K13: Lengkap | O13: Lengkap | S13: Ada | V13: Ada | AG13: Induksi | AK13: Hadir | AO13: < 3 Thn
G14: Separa | K14: Separa | O14: Separa | S14: Tiada | V14: Tiada | AG14: Coach | AK14: Tidak | AO14: ≥ 3 Thn
G15: Tiada | K15: Tiada | O15: Tiada | AG15: PPKSPP | AK15: THDI
A16: 5 | G16: Lengkap | K16: Lengkap | O16: Lengkap | S16: Ada | V16: Ada | AG16: Induksi | AK16: Hadir | AO16: < 3 Thn
G17: Separa | K17: Separa | O17: Separa | S17: Tiada | V17: Tiada | AG17: Coach | AK17: Tidak | AO17: ≥ 3 Thn
G18: Tiada | K18: Tiada | O18: Tiada | AG18: PPKSPP | AK18: THDI
A19: 6 | G19: Lengkap | K19: Lengkap | O19: Lengkap | S19: Ada | V19: Ada | AG19: Induksi | AK19: Hadir | AO19: < 3 Thn
G20: Separa | K20: Separa | O20: Separa | S20: Tiada | V20: Tiada | AG20: Coach | AK20: Tidak | AO20: ≥ 3 Thn
G21: Tiada | K21: Tiada | O21: Tiada | AG21: PPKSPP | AK21: THDI
A22: 7 | G22: Lengkap | K22: Lengkap | O22: Lengkap | S22: Ada | V22: Ada | AG22: Induksi | AK22: Hadir | AO22: < 3 Thn
G23: Separa | K23: Separa | O23: Separa | S23: Tiada | V23: Tiada | AG23: Coach | AK23: Tidak | AO23: ≥ 3 Thn
G24: Tiada | K24: Tiada | O24: Tiada | AG24: PPKSPP | AK24: THDI
A25: 8 | G25: Lengkap | K25: Lengkap | O25: Lengkap | S25: Ada | V25: Ada | AG25: Induksi | AK25: Hadir | AO25: < 3 Thn
G26: Separa | K26: Separa | O26: Separa | S26: Tiada | V26: Tiada | AG26: Coach | AK26: Tidak | AO26: ≥ 3 Thn
G27: Tiada | K27: Tiada | O27: Tiada | AG27: PPKSPP | AK27: THDI
A29: H. VERIFIKASI PERALATAN DI SYARIKAT / SYARIKAT LATIHAN DALAMAN (IN-HOUSE)
A30: BIL | B30: PERKARA | AB30: STATUS | AH30: BILANGAN | AM30: CATATAN
A31: 1 | B31: Premis sesuai untuk latihan praktikal | AB31: Ya / Tidak
A32: 2 | B32: Pencahayaan dalaman sesuai untuk latihan praktikal | AB32: Ya / Tidak
A33: 3 | B33: Kapasiti perantis keseluruhan jika program berjalan serentak
A35: I. VERIFIKASI PERALATAN DI SYARIKAT/AGENSI/PREMIS LUAR (jika berkaitan)
A36: BIL | B36: PROGRAM | J36: KEMUDAHAN PRAKTIKAL | Y36: MAKLUMAT SYARIKAT/AGENSI LUAR/ PUSAT LATIHAN | AL36: SYOR PEGAWAI VERIFIKASI | AR36: SYOR PEG VERIFIKASI
B37: Kod NOSS/ Tahap | F37: Cu/Duti/ WA/Task Terlibat | J37: Penilaian Proses Kerja (JPK/SLDN/PK01) | N37: Penilaian Peralatan Berdasa-rkan CU/Duti/ WA/Task (JPK/SLDN/PS01) | R37: Premis Sesuai Untuk Latihan | V37: MOU | Y37: Nama Agensi/Premis Luar | AC37: Alamat Agensi/ Premis Luar
A38: 1 | K38: Lengkap | O38: Lengkap | S38: Ya | W38: Ada | AN38: Ya | AS38: Diperaku
K39: Separa | O39: Separa | S39: Tidak | W39: Tiada | AN39: Tidak | AS39: Tidak Peraku
K40: Tiada | O40: Tiada
A41: 2 | K41: Lengkap | O41: Lengkap | S41: Ya | W41: Ada | AN41: Ya | AS41: Diperaku
K42: Separa | O42: Separa | S42: Tidak | W42: Tiada | AN42: Tidak | AS42: Tidak Peraku
...

Sheet Verifikasi SY & SI 
A1: G. VERIFIKASI PROGRAM DAN COACH DI SYARIKAT/ SYARIKAT LATIHAN DALAMAN (IN-HOUSE)
A2: Bil | B2: Kod NOSS Mengikut Tahap | F2: Kemudahan Praktikal | Q2: Kapasiti Perantis/ Tahap | T2: Bilangan Coach Layak Diperaku | W2: Catatan
F3: Proses Kerja (JPK/SLDN/PK01) | J3: Peralatan Berdasarkan CU/Duti/WA/Task (JPK/SLDN/PS01) | N3: NOSS Terkini
G4: Lengkap | K4: Diperaku | O4: Ada
G5: > Separa (70%) | K5: Tidak Diperaku | O5: Tiada
G6: Tiada (<70%) | O6: n/a
G7: Lengkap | K7: Diperaku | O7: Ada
G8: > Separa (70%) | K8: Tidak Diperaku | O8: Tiada
G9: Tiada (<70%) | O9: n/a
G10: Lengkap | K10: Diperaku | O10: Ada
G11: > Separa (70%) | K11: Tidak Diperaku | O11: Tiada
G12: Tiada (<70%) | O12: n/a
G13: Lengkap | K13: Diperaku | O13: Ada
G14: > Separa (70%) | K14: Tidak Diperaku | O14: Tiada
G15: Tiada (<70%) | O15: n/a
G16: Lengkap | K16: Diperaku | O16: Ada
G17: > Separa (70%) | K17: Tidak Diperaku | O17: Tiada
G18: Tiada (<70%) | O18: n/a
G19: Lengkap | K19: Diperaku | O19: Ada
G20: > Separa (70%) | K20: Tidak Diperaku | O20: Tiada
G21: Tiada (<70%) | O21: n/a
G22: Lengkap | K22: Diperaku | O22: Ada
G23: > Separa (70%) | K23: Tidak Diperaku | O23: Tiada
G24: Tiada (<70%) | O24: n/a
G25: Lengkap | K25: Diperaku | O25: Ada
G26: > Separa (70%) | K26: Tidak Diperaku | O26: Tiada
G27: Tiada (<70%) | O27: n/a
G28: Lengkap | K28: Diperaku | O28: Ada
G29: > Separa (70%) | K29: Tidak Diperaku | O29: Tiada
G30: Tiada (<70%) | O30: n/a
G31: Lengkap | K31: Diperaku | O31: Ada
G32: > Separa (70%) | K32: Tidak Diperaku | O32: Tiada
G33: Tiada (<70%) | O33: n/a
G34: Lengkap | K34: Diperaku | O34: Ada
G35: > Separa (70%) | K35: Tidak Diperaku | O35: Tiada
G36: Tiada (<70%) | O36: n/a
A37: H. VERIFIKASI PERALATAN DI SYARIKAT / SYARIKAT LATIHAN DALAMAN (IN-HOUSE)
A38: Bil | B38: Perkara | M38: Status/Kapasiti | U38: Catatan
A39: 1 | B39: Premis sesuai untuk latihan praktikal | M39: Ya / Tidak
A40: 2 | B40: Kapasiti perantis keseluruhan jika program berjalan serentak
...
